---
layout:     post
title:      hive 0.8运行python脚本问题
---
<div id="article_content" class="article_content clearfix csdn-tracking-statistics" data-pid="blog" data-mod="popu_307" data-dsm="post">
								<div class="article-copyright">
					版权声明：本文为博主原创文章，未经博主允许不得转载。					https://blog.csdn.net/chenyi8888/article/details/7162163				</div>
								            <link rel="stylesheet" href="https://csdnimg.cn/release/phoenix/template/css/ck_htmledit_views-f76675cdea.css">
						<div class="htmledit_views" id="content_views">
                
<p>最近在hive上执行python脚本出现了以下问题，在hive命令行里，执行时报错信息如下：</p>
<p>hive&gt;  from records                                  <br>
    &gt; select transform(year,temperature,quality)     <br>
    &gt; using 'python /user/hive/script/is_good_quality.py'    <br>
    &gt; as year,temperature;                               <br>
Total MapReduce jobs = 1<br>
Launching Job 1 out of 1<br>
Number of reduce tasks is set to 0 since there's no reduce operator<br>
Starting Job = job_201112291016_0023, Tracking URL = http://10.200.187.26:50030/jobdetails.jsp?jobid=job_201112291016_0023<br>
Kill Command = /opt/hadoop-0.20.205.0/libexec/../bin/hadoop job  -Dmapred.job.tracker=10.200.187.26:9001 -kill job_201112291016_0023<br>
Hadoop job information for Stage-1: number of mappers: 1; number of reducers: 0<br>
2011-12-29 14:56:34,192 Stage-1 map = 0%,  reduce = 0%<br>
2011-12-29 14:57:16,405 Stage-1 map = 100%,  reduce = 100%<br>
Ended Job = job_201112291016_0023 with errors<br>
Error during job, obtaining debugging information...<br>
Examining task ID: task_201112291016_0023_m_000002 (and more) from job job_201112291016_0023<br>
Exception in thread "Thread-248" java.lang.RuntimeException: Error while reading from task log url<br><span></span>at org.apache.hadoop.hive.ql.exec.errors.TaskLogProcessor.getErrors(TaskLogProcessor.java:130)<br><span></span>at org.apache.hadoop.hive.ql.exec.JobDebugger.showJobFailDebugInfo(JobDebugger.java:211)<br><span></span>at org.apache.hadoop.hive.ql.exec.JobDebugger.run(JobDebugger.java:81)<br><span></span>at java.lang.Thread.run(Thread.java:662)<br>
Caused by: java.net.ConnectException: Connection refused<br><span></span>at java.net.PlainSocketImpl.socketConnect(Native Method)<br><span></span>at java.net.PlainSocketImpl.doConnect(PlainSocketImpl.java:351)<br><span></span>at java.net.PlainSocketImpl.connectToAddress(PlainSocketImpl.java:213)<br><span></span>at java.net.PlainSocketImpl.connect(PlainSocketImpl.java:200)<br><span></span>at java.net.SocksSocketImpl.connect(SocksSocketImpl.java:366)<br><span></span>at java.net.Socket.connect(Socket.java:529)<br><span></span>at java.net.Socket.connect(Socket.java:478)<br><span></span>at sun.net.NetworkClient.doConnect(NetworkClient.java:163)<br><span></span>at sun.net.www.http.HttpClient.openServer(HttpClient.java:395)<br><span></span>at sun.net.www.http.HttpClient.openServer(HttpClient.java:530)<br><span></span>at sun.net.www.http.HttpClient.&lt;init&gt;(HttpClient.java:234)<br><span></span>at sun.net.www.http.HttpClient.New(HttpClient.java:307)<br><span></span>at sun.net.www.http.HttpClient.New(HttpClient.java:324)<br><span></span>at sun.net.www.protocol.http.HttpURLConnection.getNewHttpClient(HttpURLConnection.java:970)<br><span></span>at sun.net.www.protocol.http.HttpURLConnection.plainConnect(HttpURLConnection.java:911)<br><span></span>at sun.net.www.protocol.http.HttpURLConnection.connect(HttpURLConnection.java:836)<br><span></span>at sun.net.www.protocol.http.HttpURLConnection.getInputStream(HttpURLConnection.java:1172)<br><span></span>at java.net.URL.openStream(URL.java:1010)<br><span></span>at org.apache.hadoop.hive.ql.exec.errors.TaskLogProcessor.getErrors(TaskLogProcessor.java:120)<br><span></span>... 3 more<br></p>
<p><br></p>
<p>在hadoop的日志文件里(/opt/hadoop-0.20.205.0/logs/hadoop-root-jobtracker-chenyi3.log)，错误信息如下：</p>
<p>2011-12-29 14:57:06,865 INFO org.apache.hadoop.mapred.TaskInProgress: Error from attempt_201112291016_0023_m_000000_3: java.lang.RuntimeException: Hive Runtime Error while closing operators<br><span></span>at org.apache.hadoop.hive.ql.exec.ExecMapper.close(ExecMapper.java:226)<br><span></span>at org.apache.hadoop.mapred.MapRunner.run(MapRunner.java:57)<br><span></span>at org.apache.hadoop.mapred.MapTask.runOldMapper(MapTask.java:436)<br><span></span>at org.apache.hadoop.mapred.MapTask.run(MapTask.java:372)<br><span></span>at org.apache.hadoop.mapred.Child$4.run(Child.java:255)<br><span></span>at javax.security.auth.Subject.doAs(Subject.java:396)<br><span></span>at org.apache.hadoop.security.UserGroupInformation.doAs(UserGroupInformation.java:1059)<br><span></span>at org.apache.hadoop.mapred.Child.main(Child.java:249)<br>
Caused by: org.apache.hadoop.hive.ql.metadata.HiveException: Hit error while closing ..<br><span></span>at org.apache.hadoop.hive.ql.exec.ScriptOperator.close(ScriptOperator.java:452)<br><span></span>at org.apache.hadoop.hive.ql.exec.Operator.close(Operator.java:566)<br><span></span>at org.apache.hadoop.hive.ql.exec.Operator.close(Operator.java:566)<br><span></span>at org.apache.hadoop.hive.ql.exec.Operator.close(Operator.java:566)<br><span></span>at org.apache.hadoop.hive.ql.exec.ExecMapper.close(ExecMapper.java:193)<br><span></span>... 7 more<br></p>
<p><br></p>
<p>按照之前找到的解决方案如下：</p>
<p><span style="border-collapse:collapse;font-family:Arial, 'Liberation Sans', 'DejaVu Sans', sans-serif;font-size:14px;line-height:18px;"></span></p>
<p style="margin-left:0px;border-top-width:0px;border-right-width:0px;border-bottom-width:0px;border-left-width:0px;font-size:14px;vertical-align:baseline;background-color:transparent;clear:both;">
A few things I'd check for if I were debugging this:</p>
<p style="margin-left:0px;border-top-width:0px;border-right-width:0px;border-bottom-width:0px;border-left-width:0px;font-size:14px;vertical-align:baseline;background-color:transparent;clear:both;">
<strong>1)</strong> Is the python file set to be executable (chmod +x file.py)</p>
<p style="margin-left:0px;border-top-width:0px;border-right-width:0px;border-bottom-width:0px;border-left-width:0px;font-size:14px;vertical-align:baseline;background-color:transparent;clear:both;">
<strong>2)</strong> Make sure the python file is in the same place on all machines. Probably better - put the file in hdfs then you can use " using 'hdfs://path/to/file.py' " instead of a local path</p>
<p style="margin-left:0px;border-top-width:0px;border-right-width:0px;border-bottom-width:0px;border-left-width:0px;font-size:14px;vertical-align:baseline;background-color:transparent;clear:both;">
<strong>3)</strong> Take a look at your job on the hadoop dashboard (http://master-node:9100), if you click on a failed task it will give you the actual java error and stack trace so you can see what actually went wrong with the execution</p>
<p style="margin-left:0px;border-top-width:0px;border-right-width:0px;border-bottom-width:0px;border-left-width:0px;font-size:14px;vertical-align:baseline;background-color:transparent;clear:both;">
<strong>4)</strong> make sure python is installed on all the slave nodes! (I always overlook this one)</p>
<p style="margin-left:0px;border-top-width:0px;border-right-width:0px;border-bottom-width:0px;border-left-width:0px;font-size:14px;vertical-align:baseline;background-color:transparent;clear:both;">
Hope that helps.....</p>
<p>还是无法执行成功，暂时无解中（如有网友知道，请告知）……………………<br><br>
通过几天的努力，终于把这个问题解决了，原因在于配置/etc/hosts文件，请参考我另一篇文章《<span style="font-family:'Microsoft YaHei';font-size:20px;line-height:30px;"><a href="http://blog.csdn.net/chenyi8888/article/details/7180290" rel="nofollow" title="Shuffle Error: Exceeded MAX_FAILED_UNIQUE_FETCHES; bailing-out." style="color:rgb(0,0,0);text-decoration:none;">Shuffle
 Error: Exceeded MAX_FAILED_UNIQUE_FETCHES; bailing-out.</a></span>》。</p>
            </div>
                </div>